<?xml version="1.0"?>
<robot xmlns:xacro="http://www.ros.org/wiki/xacro">

    <xacro:include filename="inertial_macros.xacro"/>

    <material name="white">
        <color rgba="1 1 1 1"/>
    </material>

    <material name="orange">
        <color rgba="1 0.3 0.1 1"/>
    </material>

    <material name="blue">
        <color rgba="0.2 0.2 1 1"/>
    </material>

    <material name="black">
        <color rgba="0 0 0 1"/>
    </material>

    <!-- BASE LINK -->

    <link name="base_link">

    </link>

    <!-- CHASSIS LINK -->

    <joint name="chassis_joint" type="fixed">
        <parent link="base_link"/>
        <child link="chassis"/>
        <origin xyz="-0.29 0 0"/>
    </joint>

    <link name="chassis">
        <visual>
            <origin xyz="0.29 0 0.17"/>
            <geometry>
                <box size="0.58 0.3 0.34"/>
            </geometry>
            <material name="white"/>
        </visual>
        <collision>
            <origin xyz="0.29 0 0.17"/>
            <geometry>
                <box size="0.58 0.3 0.34"/>
            </geometry>
        </collision>
        <xacro:inertial_box mass="5" x="0.58" y="0.3" z="0.34">
            <origin xyz="0.29 0 0.17" rpy="0 0 0"/>
        </xacro:inertial_box>
    </link>

    <!-- TOP CHASSIS LINK -->

    <joint name="top_chassis_joint" type="fixed">
        <parent link="base_link"/>
        <child link="top_chassis"/>
        <origin xyz="0 0 0.34"/>
    </joint>

    <link name="top_chassis">
        <visual>
            <origin xyz="0 0 0.068"/>
            <geometry>
                <box size="0.25 0.26 0.145"/>
            </geometry>
            <material name="white"/>
        </visual>
        <collision>
            <origin xyz="0 0 0.068"/>
            <geometry>
                <box size="0.25 0.26 0.145"/>
            </geometry>
            <material name="white"/>
        </collision>
        <xacro:inertial_box mass="0.5" x="0.25" y="0.26" z="0.145">
            <origin xyz="0 0 0" rpy="0 0 0"/>
        </xacro:inertial_box>
    </link>

    <!-- LEFT WHEEL LINK -->

    <joint name="left_wheel_joint" type="continuous">
        <parent link="base_link"/>
        <child link="left_wheel"/>
        <origin xyz="0 0.175 0" rpy="-${pi/2} 0 0"/>
        <axis xyz="0 0 1"/>
    </joint>

    <link name="left_wheel">
        <visual>
            <geometry>
                <cylinder radius="0.06" length="0.045"/>
            </geometry>
            <material name="blue"/>
        </visual>
        <collision>
            <geometry>
                <cylinder radius="0.06" length="0.045"/>
            </geometry>
        </collision>
        <xacro:inertial_cylinder mass="0.1" length="0.045" radius="0.06">
            <origin xyz="0 0 0" rpy="0 0 0"/>
        </xacro:inertial_cylinder>
    </link>

    <!-- RIGHT WHEEL LINK -->

    <joint name="right_wheel_joint" type="continuous">
        <parent link="base_link"/>
        <child link="right_wheel"/>
        <origin xyz="0 -0.175 0" rpy="${pi/2} 0 0"/>
        <axis xyz="0 0 -1"/>
    </joint>

    <link name="right_wheel">
        <visual>
            <geometry>
                    <cylinder radius="0.06" length="0.045"/>
            </geometry>
            <material name="blue"/>
        </visual>
        <collision>
            <geometry>
                    <cylinder radius="0.06" length="0.045"/>
            </geometry>
        </collision>
        <xacro:inertial_cylinder mass="0.1" length="0.045" radius="0.06">
            <origin xyz="0 0 0" rpy="0 0 0"/>
        </xacro:inertial_cylinder>
    </link>

    <!-- FRONT CASTER WHEEL LINK -->

    <joint name="front_caster_joint" type="fixed">
        <parent link="chassis"/>
        <child link="front_caster_wheel"/>
        <origin xyz="0.48 0 0"/>
    </joint>

    <link name="front_caster_wheel">
        <visual>
            <geometry>
                <sphere radius="0.06"/>
            </geometry>
            <material name="black"/>
        </visual>
        <collision>
            <geometry>
                <sphere radius="0.06"/>
            </geometry>
        </collision>
        <xacro:inertial_sphere mass="0.1" radius="0.06">
            <origin xyz="0 0 0" rpy="0 0 0"/>
        </xacro:inertial_sphere>
    </link>

    <!-- FRONT CASTER WHEEL LINK -->

    <joint name="back_caster_joint" type="fixed">
        <parent link="chassis"/>
        <child link="back_caster_wheel"/>
        <origin xyz="0.1 0 0"/>
    </joint>

    <link name="back_caster_wheel">
        <visual>
            <geometry>
                <sphere radius="0.06"/>
            </geometry>
            <material name="black"/>
        </visual>
        <collision>
            <geometry>
                <sphere radius="0.06"/>
            </geometry>
        </collision>
    </link>

</robot>